Traceback (most recent call last):
  File "/home/nick/garden/micromamba/envs/workshop/lib/python3.11/site-packages/jupyter_cache/executors/utils.py", line 58, in single_nb_execution
    executenb(
  File "/home/nick/garden/micromamba/envs/workshop/lib/python3.11/site-packages/nbclient/client.py", line 1305, in execute
    return NotebookClient(nb=nb, resources=resources, km=km, **kwargs).execute()
           ^^^^^^^^^^^^^^^^^^^^^^^^^^^^^^^^^^^^^^^^^^^^^^^^^^^^^^^^^^^^^^^^^^^^^
  File "/home/nick/garden/micromamba/envs/workshop/lib/python3.11/site-packages/jupyter_core/utils/__init__.py", line 168, in wrapped
    return loop.run_until_complete(inner)
           ^^^^^^^^^^^^^^^^^^^^^^^^^^^^^^
  File "/home/nick/garden/micromamba/envs/workshop/lib/python3.11/asyncio/base_events.py", line 653, in run_until_complete
    return future.result()
           ^^^^^^^^^^^^^^^
  File "/home/nick/garden/micromamba/envs/workshop/lib/python3.11/site-packages/nbclient/client.py", line 705, in async_execute
    await self.async_execute_cell(
  File "/home/nick/garden/micromamba/envs/workshop/lib/python3.11/site-packages/nbclient/client.py", line 1058, in async_execute_cell
    await self._check_raise_for_error(cell, cell_index, exec_reply)
  File "/home/nick/garden/micromamba/envs/workshop/lib/python3.11/site-packages/nbclient/client.py", line 914, in _check_raise_for_error
    raise CellExecutionError.from_cell_and_msg(cell, exec_reply_content)
nbclient.exceptions.CellExecutionError: An error occurred while executing the following cell:
------------------
path = "../data/On_Time_Reporting_Carrier_On_Time_Performance_(1987_present)_2023_1.csv"
data = CSV.read(path, DataFrame)
typeof(data, 5)
------------------


ArgumentError: typeof: too many arguments (expected 1)

Stacktrace:
 [1] top-level scope
   @ In[2]:3

